2025-07-02 11:03:53,073 | ERROR | Ошибка в send_system_stats: Telegram server says - Bad Request: chat not found
Traceback (most recent call last):
  File "/app/src/infrastructure/taskiq/tasks.py", line 65, in send_system_stats
    await bot.send_message(chat_id='reherherhrehre', text=msg, parse_mode='HTML')
  File "/usr/local/lib/python3.12/site-packages/aiogram/client/bot.py", line 2850, in send_message
    return await self(call, request_timeout=request_timeout)
           ^^^^^^^^^^^^^^^^^^^^^^^^^^^^^^^^^^^^^^^^^^^^^^^^^
  File "/usr/local/lib/python3.12/site-packages/aiogram/client/bot.py", line 478, in __call__
    return await self.session(self, method, timeout=request_timeout)
           ^^^^^^^^^^^^^^^^^^^^^^^^^^^^^^^^^^^^^^^^^^^^^^^^^^^^^^^^^
  File "/usr/local/lib/python3.12/site-packages/aiogram/client/session/base.py", line 254, in __call__
    return cast(TelegramType, await middleware(bot, method))
                              ^^^^^^^^^^^^^^^^^^^^^^^^^^^^^
  File "/usr/local/lib/python3.12/site-packages/aiogram/client/session/aiohttp.py", line 185, in make_request
    response = self.check_response(
               ^^^^^^^^^^^^^^^^^^^^
  File "/usr/local/lib/python3.12/site-packages/aiogram/client/session/base.py", line 120, in check_response
    raise TelegramBadRequest(method=method, message=description)
aiogram.exceptions.TelegramBadRequest: Telegram server says - Bad Request: chat not found
2025-07-02 11:04:02,280 | ERROR | Ошибка в send_system_stats: Telegram server says - Bad Request: chat not found
Traceback (most recent call last):
  File "/app/src/infrastructure/taskiq/tasks.py", line 65, in send_system_stats
    await bot.send_message(chat_id='reherherhrehre', text=msg, parse_mode='HTML')
  File "/usr/local/lib/python3.12/site-packages/aiogram/client/bot.py", line 2850, in send_message
    return await self(call, request_timeout=request_timeout)
           ^^^^^^^^^^^^^^^^^^^^^^^^^^^^^^^^^^^^^^^^^^^^^^^^^
  File "/usr/local/lib/python3.12/site-packages/aiogram/client/bot.py", line 478, in __call__
    return await self.session(self, method, timeout=request_timeout)
           ^^^^^^^^^^^^^^^^^^^^^^^^^^^^^^^^^^^^^^^^^^^^^^^^^^^^^^^^^
  File "/usr/local/lib/python3.12/site-packages/aiogram/client/session/base.py", line 254, in __call__
    return cast(TelegramType, await middleware(bot, method))
                              ^^^^^^^^^^^^^^^^^^^^^^^^^^^^^
  File "/usr/local/lib/python3.12/site-packages/aiogram/client/session/aiohttp.py", line 185, in make_request
    response = self.check_response(
               ^^^^^^^^^^^^^^^^^^^^
  File "/usr/local/lib/python3.12/site-packages/aiogram/client/session/base.py", line 120, in check_response
    raise TelegramBadRequest(method=method, message=description)
aiogram.exceptions.TelegramBadRequest: Telegram server says - Bad Request: chat not found
2025-07-02 11:05:02,280 | ERROR | Ошибка в send_system_stats: Telegram server says - Bad Request: chat not found
Traceback (most recent call last):
  File "/app/src/infrastructure/taskiq/tasks.py", line 65, in send_system_stats
    await bot.send_message(chat_id=ADMIN_CHAT_ID, text=msg, parse_mode='HTML')
  File "/usr/local/lib/python3.12/site-packages/aiogram/client/bot.py", line 2850, in send_message
    return await self(call, request_timeout=request_timeout)
           ^^^^^^^^^^^^^^^^^^^^^^^^^^^^^^^^^^^^^^^^^^^^^^^^^
  File "/usr/local/lib/python3.12/site-packages/aiogram/client/bot.py", line 478, in __call__
    return await self.session(self, method, timeout=request_timeout)
           ^^^^^^^^^^^^^^^^^^^^^^^^^^^^^^^^^^^^^^^^^^^^^^^^^^^^^^^^^
  File "/usr/local/lib/python3.12/site-packages/aiogram/client/session/base.py", line 254, in __call__
    return cast(TelegramType, await middleware(bot, method))
                              ^^^^^^^^^^^^^^^^^^^^^^^^^^^^^
  File "/usr/local/lib/python3.12/site-packages/aiogram/client/session/aiohttp.py", line 185, in make_request
    response = self.check_response(
               ^^^^^^^^^^^^^^^^^^^^
  File "/usr/local/lib/python3.12/site-packages/aiogram/client/session/base.py", line 120, in check_response
    raise TelegramBadRequest(method=method, message=description)
aiogram.exceptions.TelegramBadRequest: Telegram server says - Bad Request: chat not found
2025-07-03 11:00:02,057 | ERROR | Ошибка в send_system_stats: HTTP Client says - ClientConnectorDNSError: Cannot connect to host api.telegram.org:443 ssl:default [Temporary failure in name resolution]
Traceback (most recent call last):
  File "/usr/local/lib/python3.12/site-packages/aiohttp/connector.py", line 1357, in _create_direct_connection
    hosts = await self._resolve_host(host, port, traces=traces)
            ^^^^^^^^^^^^^^^^^^^^^^^^^^^^^^^^^^^^^^^^^^^^^^^^^^^
  File "/usr/local/lib/python3.12/site-packages/aiohttp/connector.py", line 995, in _resolve_host
    return await asyncio.shield(resolved_host_task)
           ^^^^^^^^^^^^^^^^^^^^^^^^^^^^^^^^^^^^^^^^
  File "/usr/local/lib/python3.12/site-packages/aiohttp/connector.py", line 1026, in _resolve_host_with_throttle
    addrs = await self._resolver.resolve(host, port, family=self._family)
            ^^^^^^^^^^^^^^^^^^^^^^^^^^^^^^^^^^^^^^^^^^^^^^^^^^^^^^^^^^^^^
  File "/usr/local/lib/python3.12/site-packages/aiohttp/resolver.py", line 39, in resolve
    infos = await self._loop.getaddrinfo(
            ^^^^^^^^^^^^^^^^^^^^^^^^^^^^^
  File "uvloop/loop.pyx", line 1529, in getaddrinfo
socket.gaierror: [Errno -3] Temporary failure in name resolution

The above exception was the direct cause of the following exception:

Traceback (most recent call last):
  File "/usr/local/lib/python3.12/site-packages/aiogram/client/session/aiohttp.py", line 177, in make_request
    async with session.post(
  File "/usr/local/lib/python3.12/site-packages/aiohttp/client.py", line 1425, in __aenter__
    self._resp: _RetType = await self._coro
                           ^^^^^^^^^^^^^^^^
  File "/usr/local/lib/python3.12/site-packages/aiohttp/client.py", line 703, in _request
    conn = await self._connector.connect(
           ^^^^^^^^^^^^^^^^^^^^^^^^^^^^^^
  File "/usr/local/lib/python3.12/site-packages/aiohttp/connector.py", line 548, in connect
    proto = await self._create_connection(req, traces, timeout)
            ^^^^^^^^^^^^^^^^^^^^^^^^^^^^^^^^^^^^^^^^^^^^^^^^^^^
  File "/usr/local/lib/python3.12/site-packages/aiohttp/connector.py", line 1056, in _create_connection
    _, proto = await self._create_direct_connection(req, traces, timeout)
               ^^^^^^^^^^^^^^^^^^^^^^^^^^^^^^^^^^^^^^^^^^^^^^^^^^^^^^^^^^
  File "/usr/local/lib/python3.12/site-packages/aiohttp/connector.py", line 1363, in _create_direct_connection
    raise ClientConnectorDNSError(req.connection_key, exc) from exc
aiohttp.client_exceptions.ClientConnectorDNSError: Cannot connect to host api.telegram.org:443 ssl:default [Temporary failure in name resolution]

During handling of the above exception, another exception occurred:

Traceback (most recent call last):
  File "/app/src/infrastructure/taskiq/tasks.py", line 65, in send_system_stats
    )
  File "/usr/local/lib/python3.12/site-packages/aiogram/client/bot.py", line 2850, in send_message
    return await self(call, request_timeout=request_timeout)
           ^^^^^^^^^^^^^^^^^^^^^^^^^^^^^^^^^^^^^^^^^^^^^^^^^
  File "/usr/local/lib/python3.12/site-packages/aiogram/client/bot.py", line 478, in __call__
    return await self.session(self, method, timeout=request_timeout)
           ^^^^^^^^^^^^^^^^^^^^^^^^^^^^^^^^^^^^^^^^^^^^^^^^^^^^^^^^^
  File "/usr/local/lib/python3.12/site-packages/aiogram/client/session/base.py", line 254, in __call__
    return cast(TelegramType, await middleware(bot, method))
                              ^^^^^^^^^^^^^^^^^^^^^^^^^^^^^
  File "/usr/local/lib/python3.12/site-packages/aiogram/client/session/aiohttp.py", line 184, in make_request
    raise TelegramNetworkError(method=method, message=f"{type(e).__name__}: {e}")
aiogram.exceptions.TelegramNetworkError: HTTP Client says - ClientConnectorDNSError: Cannot connect to host api.telegram.org:443 ssl:default [Temporary failure in name resolution]
2025-07-04 11:10:02,255 | ERROR | Ошибка в send_system_stats: Telegram server says - Flood control exceeded on method 'SendMessage' in chat 6678098250. Retry in 1800 seconds.
Original description: Too Many Requests: retry after 1800
(background on this error at: https://core.telegram.org/bots/faq#my-bot-is-hitting-limits-how-do-i-avoid-this)
Traceback (most recent call last):
  File "/app/src/infrastructure/taskiq/tasks.py", line 68, in send_system_stats
    await bot.send_message(chat_id=ADMIN_CHAT_ID, text=msg, parse_mode='HTML')
  File "/usr/local/lib/python3.12/site-packages/aiogram/client/bot.py", line 2850, in send_message
    return await self(call, request_timeout=request_timeout)
           ^^^^^^^^^^^^^^^^^^^^^^^^^^^^^^^^^^^^^^^^^^^^^^^^^
  File "/usr/local/lib/python3.12/site-packages/aiogram/client/bot.py", line 478, in __call__
    return await self.session(self, method, timeout=request_timeout)
           ^^^^^^^^^^^^^^^^^^^^^^^^^^^^^^^^^^^^^^^^^^^^^^^^^^^^^^^^^
  File "/usr/local/lib/python3.12/site-packages/aiogram/client/session/base.py", line 254, in __call__
    return cast(TelegramType, await middleware(bot, method))
                              ^^^^^^^^^^^^^^^^^^^^^^^^^^^^^
  File "/usr/local/lib/python3.12/site-packages/aiogram/client/session/aiohttp.py", line 185, in make_request
    response = self.check_response(
               ^^^^^^^^^^^^^^^^^^^^
  File "/usr/local/lib/python3.12/site-packages/aiogram/client/session/base.py", line 110, in check_response
    raise TelegramRetryAfter(
aiogram.exceptions.TelegramRetryAfter: Telegram server says - Flood control exceeded on method 'SendMessage' in chat 6678098250. Retry in 1800 seconds.
Original description: Too Many Requests: retry after 1800
(background on this error at: https://core.telegram.org/bots/faq#my-bot-is-hitting-limits-how-do-i-avoid-this)
